Workbook

Sheet 읽는 법
B2: 보험금 지급 규칙표 — 검수용
B3: 메리츠 스마트 제안서 생성기 v8.70 · rules.json 의 규칙 111줄
B5: 이 표가 하는 일
B6: 고객 설계서에서 담보명을 하나 읽으면, 이 표를 위에서부터 훑어 처음 걸리는 한 줄로 그 담보를 계산합니다.
B7: 두 줄에 다 걸려도 위에 있는 줄만 쓰기 때문에 「순번」이 곧 우선순위입니다. 순서를 바꾸면 계산이 바뀝니다.
B8: 어느 줄에도 걸리지 않으면 금액을 만들지 않고 사유만 남깁니다 — 틀린 금액이 아니라 빈칸으로 나타납니다.
B10: 무엇을 봐 주셔야 하나
B11: 1. 「담보명 조건」이 우리 담보를 제대로 집어내는지 — 빠진 담보, 엉뚱하게 걸리는 담보
B12: 2. 「지급 횟수」가 약관과 맞는지 — 최초 1회인데 연 1회로 적혀 있지 않은지
B13: 3. 「그 밖의 조건」이 약관 조건을 빠뜨리지 않았는지 — 병원 종별, 며칠 이상, 몇 종 이상
B14: 4. 「적용 담보 수」가 0인 줄 — 지금 마스터에 걸리는 담보가 없는 규칙입니다
B15: 5. 「지급 사유 문구」가 고객에게 그대로 인쇄되는 문장이므로 표현이 맞는지
... B33: 제외 상품·고지 꼬리표 — 지면을 붙이지 않는 상품, 담보명 뒤에서 떼어 내는 꼬리표.

Sheet 규칙 111개
A1: 순번 | B1: 규칙 ID | C1: 보상 유형 | D1: 담보명 조건 | E1: 제외 조건 | F1: 질병코드(KCD) 판정 | G1: 사례 금액 계산 | H1: 지급 횟수 | I1: 필요한 치료행위 | J1: 모두 필요한 치료행위 | K1: 질병 계열 | L1: 그 밖의 조건 | M1: 지면 묶음 | N1: 지급 사유 문구 | O1: 규칙 설명(메모) | P1: 적용 담보 수 | Q1: 0건인 이유 | R1: 적용 담보 예시 | S1: 검수 결과 | T1: 검수 의견
A2: 위에서부터 검사하는 순서. 먼저 걸린 규칙 하나만 적용된다 | B2: 코드에서 쓰는 이름 | C2: 이 담보를 어떤 보상으로 계산할지 | D2: 담보명이 이 조건에 걸리면 이 규칙을 쓴다 (| 는 "또는") | E2: 담보명이 여기에 걸리면 이 규칙을 쓰지 않고 다음 줄로 넘어간다 | F2: 고객의 질병코드를 무엇과 대조해 지급 여부를 정하는가 | G2: 치료사례 지면에서 금액을 계산하는 유형인가 (아니면 담보 분류만) | H2: 한 사례에서 몇 번까지 지급하는가 | I2: 사례에서 이 치료를 받았어야 지급 (하나라도 해당되면) | J2: 나열된 치료를 모두 받았을 때만 지급 | K2: 사례가 선언한 질병 계열 한정 | L2: 위 칸으로 안 적히는 조건들 | M2: 제안서에서 어느 묶음으로 보여주는가 | N2: 제안서에 "왜 지급되는가"로 인쇄되는 문장 | O2: 규칙을 넣은 이유·근거 (코드 주석) | P2: 특약 마스터 1,758건 중 이 규칙에 걸리는 담보 수 | Q2: 적용 담보가 0건인 줄만 채워집니다 — 이름이 없는 것인지, 위쪽 줄이 먼저 잡아가는 것인지 | R2: 실제로 걸린 담보 이름 (최대 5건) | S2: 검수자가 적는 칸 — O / X / 보류 | T2: 검수자가 적는 칸
A3: 1 | B3: skip_admin | C3: 계산 제외 (제도성·조건부) | D3: 지정대리청구|보험료납입지원|납입면제|건강관리서비스|보험료할인 | F3: 질병코드 조건 없음 — 담보명·치료행위로만 판정 | G3: 분류만 (금액 계산 안 함) | H3: — | O3: 제도성·서비스 특약 (보험금 지급 담보 아님) | P3: 9 | R3: 보험료납입지원(유사암진단)(2종) 보험료납입지원(유사암진단)(3종) 보험료납입지원(유사암진단) 운전자용 보험료납입면제진단비 (교통상해50% 및 자동차사고부상(1-7급)) 비운전자용 보험료납입면제진단비 (교통상해50% 및 자동차사고부상(1-7급))
A4: 2 | B4: tx_hc | C4: 치료비 (치료행위) | D4: (대장용종제거수술비|장루\(인공항문\)조성및폐쇄수술비|체외충격파쇄석술치료비|특정NGS유전자패널검사비|자궁경부원추형절제술치료비|특정단순창상봉합술치료비|견봉성형술및회전근개파열술치료비) | F4: 약관 별표 진료행위(수가)코드와 대조 | G4: 계산함 | H4: 연 1회 | M4: 치료비 | N4: 약관 별표 진료행위(수가코드)에 해당하는 치료 · 연간 1회 | O4: 진료행위(수가)코드로 정한 치료비 — 별표 수가코드 ∩ 사례 단계 수가코드로 판정(v8.14) | P4: 11 | R4: 갱신형 특정NGS유전자패널검사비 (급여,연간1회한) 갱신형 특정NGS유전자패널검사비 (급여,연간1회한) 갱신형 체외충격파쇄석술치료비 (급여,연간1회한) 특정단순창상봉합술치료비 (급여,연간3회한) 견봉성형술 및 회전근개파열술치료비(급여,연간1회한)
A5: 3 | B5: dx_cancer_group30 | C5: 진단비 | D5: 암종별\(30종\)통합암진단비 | F5: 질병코드 그룹표(rules.json)와 대조 | G5: 계산함 | H5: 최초 1회 | K5: 암 | M5: 진단비 | N5: 약관 별표 암종구분에 해당하는 암 진단확정 · 암종별 각각 최초 1회 | O5: 암종별(30종)통합암진단비 — 세부급부 [암종구분]을 kcd_groups(별표24/43)로 판정 · 다른 원발암이 생기면 그 암종에서 다시 지급(v8.12) | P5: 124 | R5: 암종별(30종)통합암진단비(유사암제외) 암종별(30종)통합암진단비(유사암제외)[입술,혀 및 구강암] 암종별(30종)통합암진단비(유사암제외)[주침샘,편도,인두 및 구강기타암] 암종별(30종)통합암진단비(유사암제외)[특정소화기암Ⅱ] 암종별(30종)통합암진단비(유사암제외)[위암]
A6: 4 | B6: dx_recur | C6: 진단비 | D6: 재진단암진단비|재발암및잔여암진단비 | F6: 암 — 유사암 제외 (약관 별표 암분류로 판정) | G6: 계산함 | H6: 최초 1회 | K6: 암 | L6: 재진단 단계에서만 (첫 진단 단계에서는 계산 안 함) | M6: 진단비 | N6: 첫번째암 진단 후 대기기간(1·2·5년) 경과 뒤 재진단·재발 시 | O6: 재진단암·재발암및잔여암 진단비 — 첫 진단 단계에서는 0원, 사례의 재진단 단계에서만 지급(v8.12) | P6: 8 | R6: 재진단암진단비(1년 대기형) 갱신형 재진단암진단비(1년 대기형) 재진단암진단비(5년대기형,기타피부암,갑상선암및전립선암포함) 재진단암진단비(2년대기형) 재진단암진단비(5회한,1년대기형,기타피부암,갑상선암및전립선암포함)
A7: 5 | B7: day_daycare | C7: 입원·통원 일당 | D7: 낮병동입원일당 | F7: 암 또는 유사암 | G7: 계산함 | H7: 받을 때마다 (기본값) | L7: 지급 단위 : 낮병동 입원 1일당 | M7: 입원일당 | O7: 암직접치료 낮병동입원일당(급여) — 낮병동 입원 1일당 · 연간 한도는 담보명 'N일한도'에서(v8.12) | P7: 2 | R7: 종합병원암직접치료낮병동입원일당(급여,1일1회한,연간20일한도) 종합병원암직접치료낮병동입원일당(급여,1일1회한,연간20일한도)
A8: 6 | B8: nonmed_drive | C8: 의료사례 비대상 (운전자·재물·법률·배상·치아) | D8: 벌금|법률비용|교통사고처리지원|변호사선임|형사합의|면허정지|면허취소|자동차사고부상치료비|차량손해|렌트|견인|운반비용|취득세|보복운전|자동차사고성형|자전거사고|대중교통이용중|변호사|소송|출석비용 | F8: 질병코드 조건 없음 — 담보명·치료행위로만 판정 | G8: 분류만 (금액 계산 안 함) | H8: — | O8: 운전자·교통 비용담보 | P8: 55 | R8: 민사소송법률비용 의료사고법률비용 행정소송법률비용 대중교통이용중 교통상해후유장해(3-100%) 의료사고법률비용
A9: 7 | B9: nonmed_prop | C9: 의료사례 비대상 (운전자·재물·법률·배상·치아) | D9: 가전제품|누출손해|임시거주비|붕괴|스프링클러|도난|골프용품|홀인원|알바트로스|직거래사기|명예훼손|층간소음|강력범죄|배상책임|재물|화재|풍수재|배터리|차액지원 | F9: 질병코드 조건 없음 — 담보명·치료행위로만 판정 | G9: 분류만 (금액 계산 안 함) | H9: — | O9: 재물·배상·생활 비용담보 | P9: 46 | R9: 20대가전제품 고장수리비용 12대가전제품 고장수리비용 신8대가전제품 고장수리비용 갱신형 가족일상생활중배상책임(Ⅳ) 강력범죄피해(일상생활중)
A10: 8 | B10: nonmed_dental | C10: 의료사례 비대상 (운전자·재물·법률·배상·치아) | D10: 치아|임플란트|보철|크라운|인레이|온레이|틀니|치조골|충전치료|치주 | E10: 치아파절|치아탈구 | F10: 질병코드 조건 없음 — 담보명·치료행위로만 판정 | G10: 분류만 (금액 계산 안 함) | H10: — | O10: 치아·구강 담보 — '치아파절 제외/포함'은 골절·상해수술 담보의 꼬리말이지 치아 담보가 아니다(v8.61) | P10: 30 | R10: 자동차사고치아보철치료비 갱신형 치아보철치료비보장(임플란트 무제한)(2년감액형) 갱신형 치아보철치료비보장(임플란트 무제한)(1년감액형) 갱신형 치아보철치료비보장(임플란트 연간3개한)(2년감액형) 갱신형 치아보철치료비보장(임플란트 연간3개한)(1년감액형)
A11: 9 | B11: skip_rate_table | C11: 계산 제외 (제도성·조건부) | D11: 신골절치료비|신깁스치료비|상해흉터복원수술비|한방치료비 | F11: 질병코드 조건 없음 — 담보명·치료행위로만 판정 | G11: 분류만 (금액 계산 안 함) | H11: — | L11: 기록 사유 : 가입금액에 약관 지급률표·회당 비율·cm당 금액을 곱해 정하는 담보(신골절치료비·신깁스치료비 = 별표 지급률표 × 가입금액, 상해흉터복원수술비 = 수술 1cm당 14만원·7만원(500만원 한도), 한방치료비 = 첩약 1회당 100%·약침 1회당 20%) — 지급률표가 데이터에 없어 사례 계산 제외 | O11: 지급률·회당·cm당 금액 담보 — 가입금액 전액이 붙지 않게 계산 제외 + 사유 기록(v8.61) | P11: 16 | R11: 신골절치료비(치아파절포함) 상해흉터복원수술비 신골절치료비(치아파절포함) 갱신형 신골절치료비(치아파절포함) 신깁스치료비
A12: 10 | B12: skip_conditional | C12: 계산 제외 (제도성·조건부) | D12: 호스피스|생식세포동결|안전사고피해치료비|중대한재생불량성빈혈진단비 | F12: 질병코드 조건 없음 — 담보명·치료행위로만 판정 | G12: 분류만 (금액 계산 안 함) | H12: — | L12: 기록 사유 : 질병코드가 아니라 상태·행위 조건으로 지급사유를 정하는 담보(말기암 호스피스전문기관 입원형·가정형 치료, 암 진단 후 생식세포 동결, 폭력사고 확인서, 재생불량성빈혈의 혈액검사 수치 기준) — 사례로 단정할 수 없어 계산 제외 | O12: 상태·행위 조건부 담보 — 계산 제외 + 사유 기록(v8.61) | P12: 4 | R12: 안전사고피해치료비 중대한재생불량성빈혈진단비 말기암호스피스완화치료(입원형및가정형) 갱신형암진단후생식세포동결보존비(최초1회한)
A13: 11 | B13: skip_subhc_shared | C13: 계산 제외 (제도성·조건부) | D13: 특정급여시술치료비|특정비급여,신의료기술치료비|철심제거수술비|부목치료비|^(신경차단술|단순창상봉합술),연간1회한$ | F13: 질병코드 조건 없음 — 담보명·치료행위로만 판정 | G13: 분류만 (금액 계산 안 함) | H13: — | L13: 기록 사유 : 약관은 세부보장(흡인·천자 / 신경차단술 / 화상처치 / 도수정복술 / 단순창상봉합술 / 기타시술, 1종~4종, 철심제거·부목)마다 다른 수가코드를 열거하지만 특약 마스터의 세부보장 수가코드 목록이 부모 담보 전체 목록과 같아 세부별로 가를 수 없다 — 한 시술에 세부보장 전부가 지급되지 않게 계산 제외 (tool.html 별표 구분별로 나눈 뒤 kcd:'hc' 판정으로 전환) | O13: 세부보장별 수가코드 담보 — 마스터 목록이 나뉘기 전까지 계산 제외 + 사유 기록(v8.61) | P13: 53 | R13: 상해특정급여시술치료비 상해특정급여시술치료비[흡인,천자,절개,배액,배농,연간1회한] 상해특정급여시술치료비[신경차단술,연간1회한] 상해특정급여시술치료비[화상처치,연간1회한] 상해특정급여시술치료비[도수정복술,연간1회한]
A14: 12 | B14: skip_procedure_defined | C14: 계산 제외 (제도성·조건부) | D14: 조혈모세포이식수술비|5대장기이식수술비|인공관절수술비|각막이식수술비|유방절제수술복원치료비|7대장기이식대기등록 | F14: 질병코드 조건 없음 — 담보명·치료행위로만 판정 | G14: 분류만 (금액 계산 안 함) | H14: — | L14: 기록 사유 : 약관이 질병코드가 아니라 시술 자체(조혈모세포이식·5대장기이식·인공관절치환술·각막이식·유방전절제(Total Mastectomy)·이식대기등록)로 지급사유를 정하고 마스터에 수가코드 목록도 없다 — 사례에 그 시술 표시가 없어 계산 제외 | O14: 시술로 정하는 수술비(코드·수가 목록 없음) — 계산 제외 + 사유 기록(v8.61) | P14: 8 | R14: 조혈모세포이식수술비 5대장기이식수술비 유방절제수술복원치료비(부분절제제외) 인공관절수술비 각막이식수술비
A15: 13 | B15: tx_cast | C15: 치료비 (치료행위) | D15: ^(갱신형)?깁스치료비$|\[깁스치료비\]$ | F15: 질병코드 조건 없음 — 담보명·치료행위로만 판정 | G15: 계산함 | H15: 받을 때마다 | I15: ※ 이름 미정 (cast) | M15: 치료비 | N15: 깁스(Cast) 치료 | O15: 깁스치료비 — 질병코드 조건 없음(약관 제1조 '깁스(Cast)치료를 받았을 때'), 사례 단계에 깁스 치료(cast)가 있을 때만 계산(v8.61) | P15: 4 | R15: 깁스치료비 깁스치료비 통합골절치료비[깁스치료비] 깁스치료비
A16: 14 | B16: tx_trauma_center | C16: 치료비 (치료행위) | D16: 통합외상치료비 | F16: 질병코드 조건 없음 — 담보명·치료행위로만 판정 | G16: 계산함 | H16: 연 1회 (기본값) | I16: 권역외상센터 진료 (trauma_center) | L16: 원인 한정 : 상해만 | N16: 권역외상센터 중등증 이상 외상(ISS 9점 이상) 치료 · 1사고당 1회 | O16: 통합외상치료비 — 질병코드 조건 없음(ISS 점수 기준), 사례에 권역외상센터 치료가 있을 때만 계산(v8.9) | P16: 3 | R16: 통합외상치료비(권역외상센터) 통합외상치료비(권역외상센터) 통합외상치료비(권역외상센터)
A17: 15 | B17: care_nano | C17: 간병 | D17: 간호[·ㆍ]?간병통합 | F17: 질병코드 조건 없음 — 담보명·치료행위로만 판정 | G17: 분류만 (금액 계산 안 함) | H17: — | L17: 종류 : 간호·간병통합서비스 지급 방식 : 하루 | O17: 간호·간병통합병실 사용 일당 | P17: 21 | R17: 간호·간병통합서비스 사용 일반상해입원일당(181일이상)(요양,정신,한방병원제외) 간호·간병통합서비스 사용 일반상해입원일당(1일이상 180일한도) 간호·간병통합서비스 사용 질병입원일당(181일이상)(요양,정신,한방병원제외) 간호·간병통합서비스 사용 질병입원일당(1일이상 180일한도) 갱신형 간병인지원 일반상해입원일당(간 호·간병통합서비스 사용추가보장)(1일이상 180일한도)
A18: 16 | B18: care_use | C18: 간병 | D18: 간병인사용 | F18: 질병코드 조건 없음 — 담보명·치료행위로만 판정 | G18: 분류만 (금액 계산 안 함) | H18: — | L18: 종류 : 간병인사용일당 지급 방식 : 하루 | O18: 간병인 사용비용 일당 | P18: 51 | R18: 간병인사용 일반상해입원일당(plus)(1일이상 180일한도)(요양병원제외) 간병인사용 일반상해입원일당(plus)(181일이상)(요양,정신,한방병원제외) 간병인사용 일반상해입원일당(1일이상 180일한도)(요양병원) 간병인사용 일반상해입원일당(plus)(1일이상 180일한도)(요양병원제외)(체증형) 간병인사용 일반상해입원일당(1일이상 180일한도)(요양병원)(체증형)
A19: 17 | B19: care_support | C19: 간병 | D19: 간병인지원 | F19: 질병코드 조건 없음 — 담보명·치료행위로만 판정 | G19: 분류만 (금액 계산 안 함) | H19: — | L19: 종류 : 간병인지원 지급 방식 : 현물 | O19: 간병인 직접 지원(현물) | P19: 30 | R19: 갱신형 간병인지원 요양성특정질병입원일당(Ⅰ)(181일이상)(요양병원) 갱신형 간병인지원 질병입원일당(Ⅰ)(1일이상 180일한도) 갱신형 간병인지원 일반상해입원일당 (Ⅰ)(181일이상)(요양,정신,한방병원제외) 갱신형 간병인지원 질병입원일당(Ⅰ)(181일이상)(요양,정신,한방병원제외) 갱신형 간병인지원 질병입원일당(Ⅰ)(1일 이상 30일한도)
A20: 18 | B20: care_cost | C20: 간병 | D20: 간병인비용지원 | F20: 질병코드 조건 없음 — 담보명·치료행위로만 판정 | G20: 분류만 (금액 계산 안 함) | H20: — | L20: 종류 : 간병인비용지원 지급 방식 : 정액 | O20: 간병인비용 정액 지원 | P20: 16 | R20: 일반상해입원 간병인비용지원(간병인비용 200만원 이상)(요양병원제외) 일반상해입원 간병인비용지원(간병인비용 500만원 이상)(요양병원제외) 일반상해입원 간병인비용지원(간병인비용 1,000만원 이상)(요양병원제외) 일반상해입원 간병인비용지원(간병인비용 2,000만원 이상)(요양병원제외) 질병입원 간병인비용지원(간병인비용 200만원 이상)(요양병원제외)
A21: 19 | B21: care_ltc | C21: 간병 | D21: 치매간병비|장기요양급여금|치매생활비 | F21: 질병코드 조건 없음 — 담보명·치료행위로만 판정 | G21: 분류만 (금액 계산 안 함) | H21: — | L21: 종류 : 치매·장기요양 지급 방식 : 정액 | O21: 치매·장기요양 간병 | P21: 6 | R21: 장기요양급여금(1-4등급) 장기요양급여금(1-2등급) 장기요양급여금(1등급) 중증치매간병비 경증이상 치매간병비
A22: 20 | B22: life_death | C22: 사망·후유장해 | D22: 사망 | F22: 질병코드 조건 없음 — 담보명·치료행위로만 판정 | G22: 분류만 (금액 계산 안 함) | H22: — | L22: 종류 : 사망 | O22: 사망보험금 | P22: 19 | R22: 질병사망 일반상해사망 일반상해사망(추가) 갱신형 일반상해사망 질병사망
A23: 21 | B23: life_disability | C23: 사망·후유장해 | D23: 후유장해 | F23: 질병코드 조건 없음 — 담보명·치료행위로만 판정 | G23: 분류만 (금액 계산 안 함) | H23: — | L23: 종류 : 후유장해 | O23: 후유장해보험금 | P23: 68 | R23: 일반상해80%이상후유장해 질병80%이상후유장해 일반상해80%이상후유장해 생활자금 일반상해50%이상후유장해 생활자금 일반상해50%이상후유장해
A24: 22 | B24: itc_unknown | C24: 계산 제외 + 사유 기록 | D24: 통합치료비 | F24: 질병코드 조건 없음 — 담보명·치료행위로만 판정 | G24: 분류만 (금액 계산 안 함) | H24: — | O24: [v8.3: 약관 지급금액표(product_data.json)에 연동되지 않은 통합치료비. 정액 치료비(tx_etc_care)로 흘러가 오계산되던 것을 계산 제외+로그로 바꿈] | P24: 46 | R24: 상해 통합치료비(실속형) 특정순환계질환 통합치료비 상급종합병원,권역심뇌혈관질환센터 특정순환계질환 통합치료비 암 통합치료비(기본형) 암 통합치료비(실속형)
A25: 23 | B25: tx_thromb_combo | C25: 치료비 (치료행위) | D25: 특정혈전치료비 | F25: 특약 마스터(db.json)에 실린 약관 KCD 목록과 대조 | G25: 계산함 | H25: 연 1회 | I25: 혈전용해치료(약물) (thromb) 기계적 혈전제거술 (thrombectomy) | J25: 혈전용해치료(약물) (thromb) 기계적 혈전제거술 (thrombectomy) | M25: 치료비 | N25: 혈전용해치료 + 급여 기계적혈전제거술을 모두 받은 때 · 연간 1회 | O25: 뇌혈관·허혈성심장질환 특정혈전치료비 — 두 치료를 모두 받아야 지급(약관 제1조) | P25: 6 | R25: 뇌혈관질환진단및치료비Ⅱ[뇌혈관질환 특정혈전치료비(연간1회한)] 허혈성심장질환진단및치료비Ⅱ[허혈성심장질환 특정혈전치료비(연간1회한)] 뇌혈관질환진단및치료비[뇌혈관질환 특정혈전치료비(연간1회한)] 허혈성심장질환진단및치료비[허혈성심장질환 특정혈전치료비(연간1회한)] 뇌혈관질환진단및치료비Ⅱ[뇌혈관질환 특정혈전치료비(연간1회한)]
A26: 24 | B26: dx_cancer_stage4 | C26: 계산 제외 (제도성·조건부) | D26: 원격전이포함4기 | F26: 질병코드 조건 없음 — 담보명·치료행위로만 판정 | G26: 분류만 (금액 계산 안 함) | H26: — | L26: 기록 사유 : 원격전이(4기) 진단 시에만 지급되는 조건부 진단비 — 일반 암 진단 사례에서는 계산에서 제외 | O26: 원격전이포함 4기 진단비 — 병기 조건부(사례 계산 제외) | P26: 18 | R26: 원격전이포함 4기 통합암진단비(유사암제외) 원격전이포함 4기 기타피부암 및 갑상선암진단비 원격전이포함 4기 통합암진단비(유사암제외) 원격전이포함 4기 기타피부암 및 갑상선암진단비 원격전이포함4기통합암진단비(유사암제외)
A27: 25 | B27: tx_cancer_main_group | C27: 치료비 (치료행위) | D27: 통합암주요치료비 | F27: 질병코드 그룹표(rules.json)와 대조 | G27: 계산함 | H27: 연 1회 | I27: 수술 (surg) 항암 화학약물치료(급여) (chemo) 항암 방사선치료 (rad) | K27: 암 | M27: 암 치료 | N27: 약관 별표 암종구분에 해당하는 암의 주요치료(수술·항암약물·항암방사선) 중 하나 이상 · 연간 1회 | O27: 통합암 주요치료비 — 암종 그룹별 · 주요치료 1가지만 받아도 연간 1회 | P27: 64 | R27: 통합암 주요치료비(연간1회한, 10년간) 통합암 주요치료비(체증형)(연간1회한, 10년간) 상급종합병원,국립암센터 통합암 주요치료비(연간1회한, 10년간) 상급종합병원,국립암센터 통합암 주요 치료비(체증형)(연간1회한, 10년간) 통합암 주요치료비(연간1회한, 10년간)
A28: 26 | B28: skip_parent_composite | C28: 계산 제외 (제도성·조건부) | D28: ^(\(\d+년갱신\))?(갱신형)?(통합전이암진단비|통합골절치료비|신화상치료비|통합암진단비\(전이포함\)\(유사암제외\)|통합암진단비\(유사암제외\)|특정질환3대치료비|암진단및치료비Ⅱ|통합항암방사선약물치료비\(최대8회한\)|표적항암약물허가치료비\(연간약물종류개수별\)(\(비급여\(전액본인부담포함\)\))?\(연간1회한\))$ | F28: 질병코드 조건 없음 — 담보명·치료행위로만 판정 | G28: 분류만 (금액 계산 안 함) | H28: — | L28: 기록 사유 : 세부보장 여러 개로 구성된 부모 담보(통합전이암진단비 4개 · 통합골절치료비 5개 · 통합암진단비(전이포함)(유사암제외)·통합암진단비(유사암제외) 5개) — 약관 제1조가 지급사유를 세부보장마다 따로 정하므로 설계서의 세부보장 행(예 통합암진단비(전이포함)(유사암제외)(특정소화기암(전이포함)진단비) · 통합전이암진단비[림프절전이암(암(유사암제외))진단비])으로 각각 계산하고 부모 행은 계산하지 않음. 마스터의 부모 KCD 목록은 세부보장 목록의 합집합이라 부모 이름으로 계산하면 원발암 진단만으로 전이암진단비가, 골절 진단만으로 골절치료비가 붙는다(v8.62) | O28: 세부보장으로 구성된 부모 담보 — 부모 행은 계산 제외 + 사유 기록(v8.62) | P28: 29 | R28: 신화상치료비 통합암진단비 (전이포함)(유사암제외) 갱신형 표적항암약물허가치료비(연간 약물종류 개수별)(연간1회한) 갱신형 표적항암약물허가치료비(연간 약물종류 개수별)(비급여(전액본인부담 포함))(연간1회한) 통합암진단비(유사암제외)
A29: 27 | B29: skip_cancer_complication | C29: 계산 제외 (제도성·조건부) | D29: 항암방사선(약물)?치료후\d+대합병증진단비|^\d+대(중증|경증)?합병증진단비$ | F29: 질병코드 조건 없음 — 담보명·치료행위로만 판정 | G29: 분류만 (금액 계산 안 함) | H29: — | L29: 기록 사유 : 암(유사암제외)·기타피부암·갑상선암 진단 후 항암방사선(약물)치료를 받고 그 날부터 1년(폐렴·뇌부종은 90일) 이내에 합병증(2대 심장질환·폐색전증 / 3대 호중구감소증·혈소판감소증·신경병증 / 5대중증·4대경증)으로 진단확정될 때 지급되는 조건부 담보(또93·또103 제2조) — 마스터 KCD 목록에 대상 암 코드와 합병증 코드가 함께 실려 있어 암 진단만으로 전액이 계산되던 것을 막는다. 사례로 단정할 수 없어 계산 제외(v8.62) | O29: 항암치료 후 합병증진단비 — 치료·기간 조건부(사례 계산 제외)(v8.62) | P29: 6 | R29: 항암방사선치료후9대합병증진단비 항암방사선치료후9대합병증진단비[5대중증합병증진단비] 항암방사선치료후9대합병증진단비[4대경증합병증진단비] 항암방사선약물치료후5대합병증진단비 항암방사선약물치료후5대합병증진단비[2대합병증진단비]
A30: 28 | B30: dx_cancer_group | C30: 진단비 | D30: (특정소액암|특정소화기암|15대특정암|14대특정암|10대특정암|4대고액암) | E30: 주요치료비|치료비|생활비|생활지원비|입원일당|통원일당|수술비|원격전이포함4기 | F30: 질병코드 그룹표(rules.json)와 대조 | G30: 계산함 | H30: 최초 1회 | K30: 암 | M30: 진단비 | N30: 약관 별표 대상 암 진단확정 · 최초 1회 | O30: 암종 그룹 진단비(별표 암종구분) — 치료비·생활비·4기 조건부 담보는 제외 [v8.3: \d+대특정암 → 별표13 그룹명으로 한정(16대특정암진단비가 dx_cancer_sub·마스터 KCD로 판정되도록)] | P30: 0 | Q30: 이름이 걸리는 담보 4건이 있으나 위쪽 줄이 먼저 잡아감 : 「dx_cancer_group30」 4건 → 이 줄이 실제로 쓰이는지, 순서를 올려야 하는지 확인 필요
A31: 29 | B31: dx_cancer_major | C31: 진단비 | D31: (^|\])(갱신형)?(통합)?암진단비|암진단및치료비.*\[암진단비|^암치료,후유장해및진단비|^암후유장해및진단비 | E31: (^|\])(갱신형)?유사암진단비|전이암|재진단암|중증갑상선암|16대특정암|5대고액치료비암|원격전이포함4기|소액암진단비|특정소액암\(|특정소화기암|\d+대특정암|\d+대고액암 | F31: 암 — 유사암 제외 (약관 별표 암분류로 판정) | G31: 계산함 | H31: 최초 1회 | K31: 암 | M31: 진단비 | N31: 암(유사암제외) 진단확정 · 최초 1회 | O31: 암진단비 — 별표3 악성신생물 분류로 판정 | P31: 21 | R31: 암진단비(유사암제외) 암진단비(유사암 및 소액암 제외) 암진단비(유사암제외)(감액및면책기간미적 용) 통합암진단비(유사암제외)(감액및면책기간 미적용) 암진단및치료비Ⅱ[암진단비(유사암제외)]
A32: 30 | B32: dx_cancer_sim | C32: 진단비 | D32: 유사암진단비 | F32: 유사암 — 제자리암·경계성종양·갑상선암·기타피부암 | G32: 계산함 | H32: 최초 1회 | K32: 암 · 유사암 | M32: 진단비 | N32: 유사암 진단확정 · 최초 1회 | O32: 유사암진단비 — 제자리암·경계성종양·기타피부암·갑상선암 | P32: 11 | R32: 유사암진단비 유사암진단비Ⅱ 유사암진단비(감액및면책기간미적용) 유사암진단비 갱신형 유사암진단비
A33: 31 | B33: dx_cancer_meta_sim | C33: 계산 제외 (제도성·조건부) | D33: (림프절전이암|특정전이암)\(기타피부암및갑상선암\) | F33: 질병코드 조건 없음 — 담보명·치료행위로만 판정 | G33: 분류만 (금액 계산 안 함) | H33: — | L33: 기록 사유 : 원발암이 기타피부암·갑상선암인 전이암에만 지급되는 세부보장 — 사례에 원발암 구분이 없어 계산 제외 | O33: 통합전이암진단비의 (기타피부암 및 갑상선암) 세부보장 — 원발암 조건부(사례 계산 제외)(v8.55) | P33: 4 | R33: 통합전이암진단비[림프절전이암(기타피부암 및 갑상선암)진단비] 통합전이암진단비[특정전이암(기타피부암 및 갑상선암)진단비] 통합전이암진단비[림프절전이암(기타피부암 및 갑상선암)진단비] 통합전이암진단비[특정전이암(기타피부암 및 갑상선암)진단비]
A34: 32 | B34: dx_cancer_meta_sim_primary | C34: 계산 제외 (제도성·조건부) | D34: 갑상선암및기타피부암의전이암 | F34: 질병코드 조건 없음 — 담보명·치료행위로만 판정 | G34: 분류만 (금액 계산 안 함) | H34: — | L34: 기록 사유 : 갑상선암(C73)·기타피부암(C44)으로 먼저 진단된 뒤 다른 기관(organ)에 전이암이 생겨야 지급되는 담보(제1조·제3조③) — 사례에 원발암 구분이 없어 계산 제외. 림프절·중피성 및 연조직·혈액 및 림프계 전이는 면책(제4조) | O34: 갑상선암 및 기타피부암의 전이암(림프절 등 전이제외)진단비(통65·또71·케125) — 원발암 조건부. 마스터 k 에 C44·C73 이 함께 실려 갑상선암 진단만으로 전이암진단비가 붙던 것을 막음(v8.61) | P34: 3 | R34: 갑상선암 및 기타피부암의 전이암 (림프절 등 전이제외)진단비 갑상선암 및 기타피부암의 전이암 (림프절 등 전이제외)진단비 갑상선암및기타피부암의전이암(림프절등전이제외)진단비
A35: 33 | B35: dx_thyroid_cond | C35: 계산 제외 (제도성·조건부) | D35: 중증갑상선암진단비|갑상선암\(초기제외\)진단비 | F35: 질병코드 조건 없음 — 담보명·치료행위로만 판정 | G35: 분류만 (금액 계산 안 함) | H35: — | L35: 기록 사유 : 갑상선암(C73) 가운데 조직형(수질암·역형성암) 또는 크기·침범·전이(2.0cm 이상 · 갑상선 밖 · 림프절/원격전이)로 정하는 담보 — 질병코드만으로 단정할 수 없어 계산 제외 | O35: 중증갑상선암진단비 · 갑상선암(초기제외)진단비 — 조직형·병기 조건부(사례 계산 제외). 마스터 k 가 C73 한 줄이라 모든 갑상선암 진단에 붙던 것을 막음(v8.61) | P35: 8 | R35: 갑상선암(초기제외)진단비 갑상선암(초기제외)진단비 중증갑상선암진단비 갱신형 중증갑상선암진단비 중증갑상선암진단비
A36: 34 | B36: dx_cancer_meta | C36: 진단비 | D36: (림프절전이암|특정전이암).*진단비 | E36: 기타피부암|갑상선암 | F36: 질병코드 그룹표(rules.json)와 대조 | G36: 계산함 | H36: 최초 1회 | K36: 암 | M36: 진단비 | N36: 약관 별표 전이암 분류표의 전이암 구분(림프절 C77 / 특정 C78~C80)에 해당하는 전이암 진단확정 · 구분별 각각 최초 1회 | O36: 전이암진단비 세부보장(림프절·특정) — 전이암 구분별로 한쪽만 지급. 마스터 목록이 C77~C80 한 줄이라 한 번의 전이로 두 세부보장이 모두 나가던 것을 고침(v8.55) | P36: 4 | R36: 통합전이암진단비[림프절전이암(암(유사암제외))진단비] 통합전이암진단비[특정전이암(암(유사암제외))진단비] 통합전이암진단비[림프절전이암(암(유사암제외))진단비] 통합전이암진단비[특정전이암(암(유사암제외))진단비]
A37: 35 | B37: dx_cancer_sub | C37: 진단비 | D37: (전이암|재진단암|중증갑상선암|갑상선암\(초기제외\)|16대특정암|5대고액치료비암|원격전이포함4기|소액암).*진단비 | F37: 특약 마스터(db.json)에 실린 약관 KCD 목록과 대조 | G37: 계산함 | H37: 최초 1회 | K37: 암 | M37: 진단비 | N37: 약관 대상 암 진단확정 · 최초 1회 | O37: 특정암·전이암 진단비 — 약관 KCD 목록 필수 | P37: 10 | R37: 5대고액치료비암진단비 16대특정암진단비 전이암진단비 전이암진단비(감액및면책기간미적용) 5대고액치료비암진단비
A38: 36 | B38: dx_terminal | C38: 계산 제외 (제도성·조건부) | D38: 말기(폐질환|신부전증|간경화)진단비 | F38: 질병코드 조건 없음 — 담보명·치료행위로만 판정 | G38: 분류만 (금액 계산 안 함) | H38: — | L38: 기록 사유 : 말기 상태로 정하는 진단비 — 말기폐질환은 영구 산소공급 + FEV1 정상예측치 25% 이하(별표), 말기신부전증은 N18 + 정기적 신장투석(제3조), 말기간경화는 복수·황달·정맥류·간성뇌증 — 질병코드만으로 단정할 수 없어 계산 제외 | O38: 말기폐질환·말기신부전증·말기간경화 진단비 — 상태 조건부(사례 계산 제외). 마스터 k(J09~J99 · N18)만 보면 폐렴·천식·만성콩팥병 진단에 전액이 붙는다(v8.61) | P38: 6 | R38: 말기폐질환진단비 말기간경화진단비 말기신부전증진단비 말기간경화진단비 말기신부전증진단비
A39: 37 | B39: dx_special_case | C39: 진단비 | D39: 산정특례대상진단비 | F39: 특약 마스터(db.json)에 실린 약관 KCD 목록과 대조 | G39: 계산함 | H39: 최초 1회 | M39: 진단비 | N39: 산정특례 등록 · 최초 1회 | O39: 중증질환자 산정특례 진단비 — 「등록된 경우」가 지급사유(등록 조건부). 암·유사암·뇌수막 양성신생물은 진단과 함께 등록, 뇌혈관·심장은 별표 수술 또는 혈전용해제 투여 단계에서 등록(scen_engine.special_reg), 그 밖(중증화상·중증외상·희귀·중증난치·결핵·중복암/재등록암)은 사례로 단정하지 않는다. dx_brain·dx_heart 보다 앞에 두어야 「중증질환자(뇌혈관질환) 산정특례대상 진단비」가 진단 단계에서 지급되지 않는다(v8.61) | P39: 27 | R39: 갱신형 중증화상환자 산정특례대상 진단비(최초1회한) 갱신형 중증질환자(뇌혈관질환) 산정특례대상 진단비(연간1회한) 갱신형 중증질환자(심장질환) 산정특례대상 진단비(연간1회한) 갱신형 중증화상환자 산정특례대상 진단비(연간1회한) 갱신형 중증외상환자 산정특례대상 진단비(연간1회한)
A40: 38 | B40: dx_circulatory | C40: 진단비 | D40: 특정순환계질환진단비 | F40: 특약 마스터(db.json)에 실린 약관 KCD 목록과 대조 | G40: 계산함 | H40: 최초 1회 | K40: 뇌질환 · 심장질환 | L40: 메모 : 약관 별표32 특정순환계질환 분류표(52코드)에 뇌혈관질환 I60~I69 가 들어 있어 뇌 진단 사례에서도 지급된다. 전에는 dx_heart(심장 계열만)에 걸려 뇌경색·뇌출혈 진단 칸에서 0 이었다(v8.62) | M40: 진단비 | N40: 약관 별표 특정순환계질환(뇌혈관 I60~I69 포함) 진단확정 · 최초 1회 | O40: 특정순환계질환진단비 — 뇌·심장 두 계열 진단에 지급(약관 별표32)(v8.62) | P40: 3 | R40: 특정순환계질환진단비 특정순환계질환진단비 갱신형 특정순환계질환진단비
...

Sheet 요약
B2: 규칙표 요약
B3: 아래 숫자는 본문 시트를 세는 수식입니다 — 본문을 고치면 함께 바뀝니다. 칸이 비어 보이면 엑셀에서 파일을 열면 자동으로 계산됩니다.
B5: 보상 유형별
B6: 보상 유형 | C6: 규칙 줄 수 | D6: 적용 담보 수
B7: 진단비 | C7: =COUNTIF('규칙 111개'!C3:C113,B7&"*") | D7: =SUMIF('규칙 111개'!C3:C113,B7&"*",'규칙 111개'!$P$3:$P$113)
B8: 수술비 | C8: =COUNTIF('규칙 111개'!C3:C113,B8&"*") | D8: =SUMIF('규칙 111개'!C3:C113,B8&"*",'규칙 111개'!$P$3:$P$113)
B9: 입원·통원 일당 | C9: =COUNTIF('규칙 111개'!C3:C113,B9&"*") | D9: =SUMIF('규칙 111개'!C3:C113,B9&"*",'규칙 111개'!$P$3:$P$113)
B10: 치료비 (치료행위) | C10: =COUNTIF('규칙 111개'!C3:C113,B10&"*") | D10: =SUMIF('규칙 111개'!C3:C113,B10&"*",'규칙 111개'!$P$3:$P$113)
B11: 간병 | C11: =COUNTIF('규칙 111개'!C3:C113,B11&"*") | D11: =SUMIF('규칙 111개'!C3:C113,B11&"*",'규칙 111개'!$P$3:$P$113)
B12: 사망·후유장해 | C12: =COUNTIF('규칙 111개'!C3:C113,B12&"*") | D12: =SUMIF('규칙 111개'!C3:C113,B12&"*",'규칙 111개'!$P$3:$P$113)
B13: 생활지원금 | C13: =COUNTIF('규칙 111개'!C3:C113,B13&"*") | D13: =SUMIF('규칙 111개'!C3:C113,B13&"*",'규칙 111개'!$P$3:$P$113)
B14: 의료사례 비대상 (운전자·재물·법률·배상·치아) | C14: =COUNTIF('규칙 111개'!C3:C113,B14&"*") | D14: =SUMIF('규칙 111개'!C3:C113,B14&"*",'규칙 111개'!$P$3:$P$113)
B15: 계산 제외 (제도성·조건부) | C15: =COUNTIF('규칙 111개'!C3:C113,B15&"*") | D15: =SUMIF('규칙 111개'!C3:C113,B15&"*",'규칙 111개'!$P$3:$P$113)
B16: 계산 제외 + 사유 기록 | C16: =COUNTIF('규칙 111개'!C3:C113,B16&"*") | D16: =SUMIF('규칙 111개'!C3:C113,B16&"*",'규칙 111개'!$P$3:$P$113)
B17: 합계 | C17: =SUM(C7:C16) | D17: =SUM(D7:D16)
B19: 지급 횟수별
B20: 지급 횟수 | C20: 규칙 줄 수 | D20: 적용 담보 수
B21: 최초 1회 | C21: =COUNTIF('규칙 111개'!H3:H113,B21&"*") | D21: =SUMIF('규칙 111개'!H3:H113,B21&"*",'규칙 111개'!$P$3:$P$113)
B22: 연 1회 | C22: =COUNTIF('규칙 111개'!H3:H113,B22&"*") | D22: =SUMIF('규칙 111개'!H3:H113,B22&"*",'규칙 111개'!$P$3:$P$113)
B23: 받을 때마다 | C23: =COUNTIF('규칙 111개'!H3:H113,B23&"*") | D23: =SUMIF('규칙 111개'!H3:H113,B23&"*",'규칙 111개'!$P$3:$P$113)
B24: — | C24: =COUNTIF('규칙 111개'!H3:H113,B24&"*") | D24: =SUMIF('규칙 111개'!H3:H113,B24&"*",'규칙 111개'!$P$3:$P$113)
B25: 합계 | C25: =SUM(C21:C24) | D25: =SUM(D21:D24)
B27: 질병코드 판정 방식별
B28: 질병코드(KCD) 판정 | C28: 규칙 줄 수 | D28: 적용 담보 수
B29: 암 — 유사암 제외 (약관 별표 암분류로 판정) | C29: =COUNTIF('규칙 111개'!F3:F113,B29&"*") | D29: =SUMIF('규칙 111개'!F3:F113,B29&"*",'규칙 111개'!$P$3:$P$113)
B30: 유사암 — 제자리암·경계성종양·갑상선암·기타피부암 | C30: =COUNTIF('규칙 111개'!F3:F113,B30&"*") | D30: =SUMIF('규칙 111개'!F3:F113,B30&"*",'규칙 111개'!$P$3:$P$113)
B31: 암 또는 유사암 | C31: =COUNTIF('규칙 111개'!F3:F113,B31&"*") | D31: =SUMIF('규칙 111개'!F3:F113,B31&"*",'규칙 111개'!$P$3:$P$113)
B32: 특약 마스터(db.json)에 실린 약관 KCD 목록과 대조 | C32: =COUNTIF('규칙 111개'!F3:F113,B32&"*") | D32: =SUMIF('규칙 111개'!F3:F113,B32&"*",'규칙 111개'!$P$3:$P$113)
B33: 131대질병 그룹표(g131.json)와 대조 | C33: =COUNTIF('규칙 111개'!F3:F113,B33&"*") | D33: =SUMIF('규칙 111개'!F3:F113,B33&"*",'규칙 111개'!$P$3:$P$113)
B34: 질병코드 그룹표(rules.json)와 대조 | C34: =COUNTIF('규칙 111개'!F3:F113,B34&"*") | D34: =SUMIF('규칙 111개'!F3:F113,B34&"*",'규칙 111개'!$P$3:$P$113)
B35: 약관 별표 진료행위(수가)코드와 대조 | C35: =COUNTIF('규칙 111개'!F3:F113,B35&"*") | D35: =SUMIF('규칙 111개'!F3:F113,B35&"*",'규칙 111개'!$P$3:$P$113)
B36: 질병코드 조건 없음 — 담보명·치료행위로만 판정 | C36: =COUNTIF('규칙 111개'!F3:F113,B36&"*") | D36: =SUMIF('규칙 111개'!F3:F113,B36&"*",'규칙 111개'!$P$3:$P$113)
B37: 합계 | C37: =SUM(C29:C36) | D37: =SUM(D29:D36)
B39: 마스터 대조
B40: 특약 마스터 담보 수 (db.json ver2611) | C40: 1758
B41: 규칙에 걸린 담보 수 | C41: 1758
B42: 어느 규칙에도 안 걸린 담보 수 | C42: 0
B43: 적용 담보가 0건인 규칙 줄 수 | C43: 8
B45: 안 걸린 담보 : 없음

Sheet 치료행위 어휘
A1: 약어 | B1: 한글 이름 | C1: 규칙에서 쓰는가
A2: anes | B2: 종합병원 전신마취 수술 | C2: 씀
A3: anes4 | B3: 4시간 이상 전신마취 수술 | C3: 씀
A4: anes6 | B4: 6시간 이상 전신마취 수술 | C4: 씀
A5: carbon | B5: 중입자 방사선치료 | C5: 씀
A6: chemo | B6: 항암 화학약물치료(급여) | C6: 씀
A7: crrt | B7: 지속적 신대체요법 | C7: 아직 안 씀
A8: ecmo | B8: 에크모(체외막산소공급) | C8: 아직 안 씀
A9: er | B9: 응급실 진료 | C9: 씀
A10: hormone | B10: 항암 호르몬약물치료 | C10: 씀
A11: hypo | B11: 저체온 치료 | C11: 아직 안 씀
A12: icu | B12: 중환자실 입원 | C12: 아직 안 씀
... A35: x_us | B35: 초음파 검사 | C35: 씀

Sheet 질병코드 그룹표
A1: 그룹 이름 | B1: 코드 수 | C1: 질병코드 (약관 별표에서 뽑은 것)
A2: 특정5대질병 | B2: 12 | C2: D12, K63.5, H25, H26, H27, J30, J31, J33, J34, L72, L84, D18
A3: 특정2대질병 | B3: 6 | C3: L84, H00, H10, B30, H60, H92
A4: 특정6대질병 | B4: 17 | C4: D12, K63.5, H25, H26, H27, J30, J31, J33, J34, L72, L84, D18, H00, H10, B30, H60, H92
A5: 특정소액암 | B5: 10 | C5: C43, C50, C53, C54, C61, C62, C65, C66, C67, D45
A6: 특정소화기암 | B6: 7 | C6: C16, C18, C19, C20, C21, C22, C26
A7: 15대특정암 | B7: 27 | C7: C00~C14, C30, C31, C32, C34, C38, C47, C49, C51, C52, C55, C56, C57, C58, C60, C63, C64, C68, C69, C74~C75, C76, C97, D46, D47.1, D47.3, D47.4, C77~C80
A8: 10대특정암 | B8: 26 | C8: C15, C17, C33, C37, C39, C45, C46, C48, C70, C71, C72, C81, C82, C83, C84, C85, C86, C88, C90, C91, C92, C93, C94, C95, C96, D47.5
A9: 4대고액암 | B9: 5 | C9: C23, C24, C25, C40, C41
A10: 특정소액암(전이포함) | B10: 15 | C10: C43, C50, C53, C54, C61, C62, C65, C66, C67, D45, C77, C79.2, C79.80, C79.88, C79.9
A11: 특정소화기암(전이포함) | B11: 16 | C11: C16, C18, C19, C20, C21, C22, C26, C78.4, C78.5, C78.6, C78.7, C78.80, C78.82, C78.88, C78.89, C79.81
A12: 14대특정암(전이포함) | B12: 30 | C12: C00~C14, C30, C31, C32, C34, C38, C47, C49, C51, C52, C55, C56, C57, C58, C60, C63, C64, C68, C69, C74~C75, C76, C97, D46, D47.1, D47.3, D47.4, C79.0, C79.1, C79.6, C80
A13: 10대특정암(전이포함) | B13: 34 | C13: C15, C17, C33, C37, C39, C45, C46, C48, C70, C71, C72, C81, C82, C83, C84, C85, C86, C88, C90, C91, C92, C93, C94, C95, C96, D47.5, C78.0, C78.1, C78.2, C78.3, C79.3, C79.4, C79.5, C79.7
... A88: 전신마취치료 항목면책(암전후관련 통합치료비) | B88: 1 | C88: K62.7

Sheet 담보명에서 읽는 조건
A1: 담보명에 이 글자가 있으면 | B1: 이렇게 읽는다 | C1: 어디에 쓰이는가
A2: 상해 · 재해 | B2: 원인을 상해로 본다 — 질병 사례에서는 계산하지 않는다 | C2: 모든 보상 유형
A3: 질병 | B3: 원인을 질병으로 본다 — 상해 사례에서는 계산하지 않는다 | C3: 모든 보상 유형
A4: 상급종합병원 | B4: 상급종합병원에서 받은 치료일 때만. 상급종합은 종합병원 조건도 함께 충족한다 | C4: 수술비 · 입원일당
A5: 종합병원 | B5: 종합병원 이상에서 받은 치료일 때만 | C5: 수술비 · 입원일당
A6: 요양병원 | B6: 요양병원 입원일 때만 | C6: 입원일당
A7: 요양병원제외 | B7: 요양병원 입원은 빼고 계산한다 (요양병원을 요구하는 조건이 아니다) | C7: 입원일당
A8: 1인실 | B8: 1인실 입원일 때만 ( "2-3인실" 이 같이 있으면 적용하지 않는다 ) | C8: 입원일당
A9: 2-3인실 | B9: 2-3인실 입원일 때만 | C9: 입원일당
A10: N일한도 | B10: 최대 N일까지만 계산한다 (예 : 180일한도) | C10: 입원일당
A11: (N일이상 | B11: N일 이상 입원했을 때부터 계산하고, N일째부터 센다 (예 : (31일이상) | C11: 입원일당
A12: [상해2종] · (질병1종) | B12: 수술 종(1~7종)을 담보명에서 읽는다 | C12: 수술비
... A19: 고지유형 꼬리표 | B19: 「제외 상품·꼬리표」 시트의 꼬리표는 규칙과 맞춰 보기 전에 떼어 낸다 | C19: 규칙 고르기

Sheet 제외 상품·꼬리표
B2: 지면을 붙이지 않는 상품 (정책으로 정한 예외)
B3: 상품명이 조건에 걸리면 계산하지 않고 원본 설계서를 그대로 돌려줍니다.
B5: 상품 이름 | C5: 상품명 조건 | D5: 왜 제외하는가
B6: 프리미엄 건강보험 · 프리미엄 간편보험 | C6: 프리미엄.{0,8}(건강|간편) | D6: 프리미엄류는 상품 구조가 다르다 — 장기유지보너스 · 단기납 · 10년 뒤 2배 체증형 담보 · 판매 채널 한정. 특히 체증 구조가 이 생성기가 쓰는 수술 회차별 체증(25%씩)과 달라 금액을 잘못 안내할 수 있다. 차후 검토 대상으로 두고 지금은 제작하지 않는다.
B9: 담보명 뒤에서 떼어 내는 고지유형 꼬리표
B10: 설계서 담보명 뒤에 붙는 꼬리표입니다. 담보명을 규칙표와 맞춰 보기 전에 떼어 냅니다.
B12: 355입원,수술고지간편가입
B13: 통합간편가입
B14: 건강가입
B15: 355간편가입
B16: 간편가입
B17: 건강고지형
B18: 통합간편고지형
B19: 355간편고지형
B20: 일반고지형
B21: 통합간편심사형
B22: 맞춤간편가입

Sheet KCD 검수 결과
A1: 심각도 | B1: 구분 | C1: 대상 그룹·규칙 | D1: 무엇이 잘못됐나 | E1: 약관 근거 | F1: 지금 들어 있는 코드 | G1: 약관대로 고치면 | H1: 영향받는 담보 | I1: 권고
A2: 높음 | B2: 제외 표시 오배정 | C2: 32대질병 · 사구체질환 | D2: 약관은 N00~N08 전부 대상이고 N08.3만 제외인데, 규칙표는 N00·N01·N02·N03·N04·N08 을 제외로 표시 | E2: 「32대질병 분류표」 p.773 | F2: !N00, !N01, !N02, !N03, !N04, N05, N06, N07, !N08, !N08.3 | G2: N00~N08 (N08.3만 제외) | H2: 32대질병관혈수술비 3건 | I2: N00~N04·N08 의 ! 를 떼고 N08.3 만 제외로 둘 것
A3: 높음 | B3: 제외 표시 오배정 | C3: 관절염,생식기질환 · 전체 | D3: 약관의 대상질병 12개 범위 중 8개가 제외로 표시됨. 포함/제외가 뒤바뀐 것으로 보임 | E3: 「관절염,생식기질환 분류표」 p.859 | F3: ! 붙음: M00~M03, M05~M14, J99.0, M15~M19, M20~M25, N70~N77, N80~N95, N99 | G3: 대상: M00~M03, M05~M14, J99.0, M15~M19, M20~M25, N40~N45, N47~N51, A59.08, B26.0, N70~N77, N80~N95, N99 / 제외: A18.01, M01.1, M14.2, A18.17, N74.0, N74.1 | H3: 현재 마스터에 걸리는 담보 없음 (이름에 관절염 들어간 특약 0건) | I3: M05.1·N51.0·N51.1 은 제외가 아니라 †* 짝 코드이므로 제외에서 빼야 함
A4: 높음 | B4: 코드 목록이 비어 있음 | C4: 특정2대질병 | D4: 그룹에 코드가 하나도 없음. 「제외」용 그룹이라 비어 있으면 제외가 작동하지 않아 보상하면 안 될 건을 보상으로 계산할 수 있음 | E4: 「질병수술비(특정2대질병제외)」 약관 제3조 ④항 | F4: (비어 있음) | G4: L84 / H00, H10, B30, H60, H92 | H4: 질병수술비(특정2대질병제외) — 통합간편·케어프리 3건 | I4: 약관 본문 표를 그대로 채울 것 (별표가 아니라 특약 본문에 있음)
A5: 높음 | B5: 코드 목록이 비어 있음 | C5: 특정6대질병 | D5: 그룹에 코드가 하나도 없음. 위와 같은 이유로 제외가 작동하지 않음 | E5: 「질병수술비(특정6대질병제외)」 약관 제3조 ④항 | F5: (비어 있음) | G5: H25, H26, H27 / J30, J31, J33, J34 / L72, L84 / D18 / H00, H10, B30, H60, H92 | H5: 질병수술비(특정6대질병제외) — 통합간편·케어프리 3건 | I5: 대장 용종·양성신생물 내시경적 절제술도 제외 대상이나 코드가 아닌 치료행위 조건이므로 따로 처리 필요
A6: 높음 | B6: 범위 기호 누락 | C6: 32대질병 · I30~I52 | D6: 약관은 I30~I52 범위로 적혀 있는데 규칙표에는 양 끝 I30·I52 두 개만 들어감 | E6: 「32대질병 분류표」 p.773 | F6: I30, I52 | G6: I30~I52 | H6: 32대질병관혈수술비(연간1회한) — 통합간편·케어프리 3건 | I6: 사이 21개를 채우거나 범위 표기(I30~I52)로 저장
A7: 높음 | B7: 범위 기호 누락 | C7: 32대질병 · I60~I69 | D7: 약관은 I60~I69 범위로 적혀 있는데 규칙표에는 양 끝 I60·I69 두 개만 들어감 | E7: 「32대질병 분류표」 p.773 | F7: I60, I69 | G7: I60~I69 | H7: 32대질병관혈수술비(연간1회한) — 통합간편·케어프리 3건 | I7: 사이 8개를 채우거나 범위 표기(I60~I69)로 저장
A8: 높음 | B8: 범위 기호 누락 | C8: 32대질병 · K70~K77 | D8: 약관은 K70~K77 범위로 적혀 있는데 규칙표에는 양 끝 K70·K77 두 개만 들어감 | E8: 「32대질병 분류표」 p.773 | F8: K70, K77 | G8: K70~K77 | H8: 32대질병관혈수술비(연간1회한) — 통합간편·케어프리 3건 | I8: 사이 6개를 채우거나 범위 표기(K70~K77)로 저장
A9: 높음 | B9: 범위 기호 누락 | C9: 32대질병 · E00~E07 | D9: 약관은 E00~E07 범위로 적혀 있는데 규칙표에는 양 끝 E00·E07 두 개만 들어감 | E9: 「32대질병 분류표」 p.773 | F9: E00, E07 | G9: E00~E07 | H9: 32대질병관혈수술비(연간1회한) — 통합간편·케어프리 3건 | I9: 사이 6개를 채우거나 범위 표기(E00~E07)로 저장
A10: 높음 | B10: 범위 기호 누락 | C10: 32대질병 · I20~I25 | D10: 약관은 I20~I25 범위로 적혀 있는데 규칙표에는 양 끝 I20·I25 두 개만 들어감 | E10: 「32대질병 분류표」 p.773 | F10: I20, I25 | G10: I20~I25 | H10: 32대질병관혈수술비(연간1회한) — 통합간편·케어프리 3건 | I10: 사이 4개를 채우거나 범위 표기(I20~I25)로 저장
A11: 높음 | B11: 범위 기호 누락 | C11: 32대질병 · I05~I09 | D11: 약관은 I05~I09 범위로 적혀 있는데 규칙표에는 양 끝 I05·I09 두 개만 들어감 | E11: 「32대질병 분류표」 p.773 | F11: I05, I09 | G11: I05~I09 | H11: 32대질병관혈수술비(연간1회한) — 통합간편·케어프리 3건 | I11: 사이 3개를 채우거나 범위 표기(I05~I09)로 저장
A12: 높음 | B12: 범위 기호 누락 | C12: 32대질병 · B15~B19 | D12: 약관은 B15~B19 범위로 적혀 있는데 규칙표에는 양 끝 B15·B19 두 개만 들어감 | E12: 「32대질병 분류표」 p.773 | F12: B15, B19 | G12: B15~B19 | H12: 32대질병관혈수술비(연간1회한) — 통합간편·케어프리 3건 | I12: 사이 3개를 채우거나 범위 표기(B15~B19)로 저장
... A18: 낮음 | B18: 담보명이 안 맞음 | C18: surg_arrhythmia (34번 규칙) | D18: 규칙은 「부정맥질환특정수술비|부정맥특정수술비」를 찾는데, 마스터에 있는 담보는 「갱신형 부정맥질환특정검사비」(검사비)임 | E18: 케어프리 특약 마스터 | F18: 부정맥질환특정수술비|부정맥특정수술비 | G18: 부정맥질환특정검사비 (검사비) | H18: 적용 담보 0건 | I18: 담보명 조건을 검사비로 고치거나, 해당 담보가 없으면 규칙을 지울 것

Sheet 빠진 코드 59개
A1: 그룹 | B1: 약관 범위 | C1: 빠진 코드 | D1: 코드 이름
A2: 32대질병 | B2: I30~I52 | C2: I31 | D2: 심장막의 기타 질환
A3: 32대질병 | B3: I30~I52 | C3: I32 | D3: 달리 분류된 질환에서의 심장막염
A4: 32대질병 | B4: I30~I52 | C4: I33 | D4: 급성 및 아급성 심내막염
A5: 32대질병 | B5: I30~I52 | C5: I34 | D5: 비류마티스성 승모판장애
A6: 32대질병 | B6: I30~I52 | C6: I35 | D6: 비류마티스성 대동맥판장애
A7: 32대질병 | B7: I30~I52 | C7: I36 | D7: 비류마티스성 삼첨판장애
A8: 32대질병 | B8: I30~I52 | C8: I37 | D8: 폐동맥판장애
A9: 32대질병 | B9: I30~I52 | C9: I38 | D9: 상세불명 판막의 심내막염
A10: 32대질병 | B10: I30~I52 | C10: I39 | D10: 달리 분류된 질환에서의 심내막염 및 심장판막장애
A11: 32대질병 | B11: I30~I52 | C11: I40 | D11: 급성 심근염
A12: 32대질병 | B12: I30~I52 | C12: I41 | D12: 달리 분류된 질환에서의 심근염
... A16: 32대질병 | B16: I30~I52 | C16: I45 | D16: 기타 전도장애
A17: 32대질병 | B17: I30~I52 | C17: I46
A18: 32대질병 | B18: I30~I52 | C18: I47 | D18: 발작성 빈맥
A19: 32대질병 | B19: I30~I52 | C19: I48 | D19: 심방세동 및 조동
A20: 32대질병 | B20: I30~I52 | C20: I49 | D20: 기타 심장부정맥
A21: 32대질병 | B21: I30~I52 | C21: I50 | D21: 심부전
A22: 32대질병 | B22: I30~I52 | C22: I51 | D22: 심장병의 불명확한 기록 및 합병증
A23: 32대질병 | B23: I60~I69 | C23: I61 | D23: 뇌내 출혈
A24: 32대질병 | B24: I60~I69 | C24: I62 | D24: 기타 비외상성 머리내 출혈
A25: 32대질병 | B25: I60~I69 | C25: I63 | D25: 뇌경색증
A26: 32대질병 | B26: I60~I69 | C26: I64 | D26: 출혈 또는 경색증으로 명시되지 않은 뇌졸중
A27: 32대질병 | B27: I60~I69 | C27: I65 | D27: 뇌경색증을 유발하지 않은 뇌전동맥의 폐쇄 및 협착
A28: 32대질병 | B28: I60~I69 | C28: I66 | D28: 뇌경색증을 유발하지 않은 대뇌동맥의 폐쇄 및 협착
A29: 32대질병 | B29: I60~I69 | C29: I67 | D29: 기타 뇌혈관질환
A30: 32대질병 | B30: I60~I69 | C30: I68 | D30: 달리 분류된 질환에서의 뇌혈관장애
A31: 32대질병 | B31: K70~K77 | C31: K71
A32: 32대질병 | B32: K70~K77 | C32: K72
A33: 32대질병 | B33: K70~K77 | C33: K73
A34: 32대질병 | B34: K70~K77 | C34: K74 | D34: 간의 섬유증 및 경변증
A35: 32대질병 | B35: K70~K77 | C35: K75
A36: 32대질병 | B36: K70~K77 | C36: K76
A37: 32대질병 | B37: E00~E07 | C37: E01
A38: 32대질병 | B38: E00~E07 | C38: E02 | D38: 무증상 요오드결핍성 갑상선기능저하증
A39: 32대질병 | B39: E00~E07 | C39: E03
A40: 32대질병 | B40: E00~E07 | C40: E04 | D40: 기타 비독성 고이터
A41: 32대질병 | B41: E00~E07 | C41: E05 | D41: 갑상선독증[갑상선기능항진증]
A42: 32대질병 | B42: E00~E07 | C42: E06
A43: 32대질병 | B43: I20~I25 | C43: I21 | D43: 급성 심근경색증
...

Sheet 이상 없던 항목
A1: 약관 분류표와 코드가 정확히 일치한 그룹
A2: 아래 그룹은 코드 하나까지 약관과 같았습니다.
A4: · 6대심장질환
A5: · 16대특정암
A6: · 5대고액치료비암
A7: · 급성심근경색증대상질병
A8: · 뇌졸중대상질병
A9: · 뇌출혈
A10: · 악성신생물(암)
A11: · 알츠하이머치매
A12: · 요양성특정질병
A13: · 유방암
... A28: · 제자리신생물에 D08 이 없는 것, 암 그룹에 C35·C36·C87·C89 가 없는 것은 KCD 에 그 번호가 없기 때문입니다 (정상)

Sheet 2차 검수 · 검사비 항목
A1: 심각도 | B1: 규칙 | C1: 대상 담보 | D1: 무엇이 잘못됐나 | E1: 약관 근거 | F1: 지금 판정 방식 | G1: 약관대로 하면 | H1: 권고
A2: 높음 | B2: [63] tx_cancer_exam | C2: 갱신형 암 특정생검조직병리검사비Ⅱ (통합간편·케어프리 2건) | D2: 약관이 진료행위코드를 낱낱이 적어 둔 항목인데, 규칙은 「조직검사를 받았는가」만 보고 지급으로 계산한다. 내시경 겸자생검·림프절 생검·피부 생검처럼 목록에 없는 검사도 지급으로 잡힌다 | E2: 제4조 — 침생검(심부) C8511·C8512·C8513·C8514 … 진료행위코드 열거 | F2: 치료행위 키(x_bio)만 대조 | G2: 열거된 진료행위코드와 대조 (목록에 있을 때만 지급) | H2: 규칙 2(tx_hc)가 이미 「약관 별표 진료행위(수가)코드와 대조」를 하고 있다. 생검만 떼어 같은 방식으로 옮기면 된다
A3: 높음 | B3: [71] tx_exam | C3: 갱신형 3대질환 MRI촬영검사비 (케어프리) | D3: 약관은 3대질환(암·유사암·뇌혈관질환·허혈성심장질환)일 때만 지급하는데, 규칙에 질병코드 조건이 없어 어떤 질병에도 MRI만 찍었으면 지급으로 계산된다 | E3: 제3조 — 「3대질환」이라 함은 암(유사암제외)·유사암·뇌혈관질환·허혈성심장질환 / 특약 마스터 보장코드 59개 | F3: 질병코드 조건 없음 | G3: 특약 마스터의 보장코드 59개와 대조 | H3: 규칙 76(tx_etc_care)처럼 「특약 마스터에 실린 약관 KCD 목록과 대조」로 바꾸면 된다
A4: 참고 | B4: [63] tx_cancer_exam | C4: 갱신형 암 내시경검사비 · MRI · CT · PET · 초음파 | D4: 이쪽은 문제 없음. 약관이 「제2부 제2장 검사료의 제4절 내시경」처럼 분류번호 구간 전체를 대상으로 해서, 치료행위 키만 봐도 결과가 같다 | E4: 제4조 — 급여 「제2부 제2장 검사료의 제4절 내시경」 분류번호 및 코드 | F4: 치료행위 키(x_endo 등) | G4: 그대로 두면 됨 | H4: 같은 규칙 안이라도 생검만 판정 방식이 달라야 한다
A5: 참고 | B5: [17] itc_unknown | C5: 통합치료비 46담보 | D5: 이번에 통합치료비 시뮬레이터에서 고친 문제(특정내시경·특정생검 수가코드)가 이 모듈에는 없다. 통합치료비를 아예 계산에서 빼고 사유만 기록하고 있기 때문 | E5: 규칙 메모 — v8.3 에서 정액 치료비로 흘러가 오계산되던 것을 계산 제외+로그로 바꿈 | F5: 분류만 (금액 계산 안 함) | G5: 현재 방식이 안전함 | H5: 나중에 통합치료비 금액을 계산하게 되면, 항목마다 수가코드 목록이 다르다는 점을 먼저 반영해야 한다
