Workbook

Sheet 사용법·출처
A1: 보험용어사전
A3: 이 파일은
A4: 약관에 나오는 어려운 보험용어를 현장에서 바로 읽을 수 있게 풀어 쓴 사전입니다.
A5: 말마다 그 말이 실제 약관이나 특약 이름에서 어떻게 쓰이는지 한 줄씩 붙였습니다.
A7: 찾는 방법
A8: · 첫 줄의 ▼ 를 눌러 분류(암·뇌심장·치아 등)로 걸러 보세요.
A9: · 특정 낱말은 Ctrl+F 로 찾으세요. 「다르게 부르는 말」 칸도 같이 찾습니다.
A10: · 「용어」 칸까지 화면에 고정돼 있어 오른쪽으로 넘겨도 무슨 말인지 보입니다.
A12: 칸 설명
A13: 쉬운 뜻 ............... 고객에게 그대로 말해도 되는 표현으로 풀어 썼습니다.
A14: 알아두기 .............. 현장에서 자주 헷갈리는 점, 놓치기 쉬운 조건입니다.
A15: 다르게 부르는 말 ...... 같은 뜻인데 약관·현장에서 달리 부르는 말입니다.
... A32: 만든 날짜 : 2026-09-21 · 세일즈혁신TF 이헌수

Sheet 보험용어사전
A1: 번호 | B1: 분류 | C1: 용어 | D1: 쉬운 뜻 | E1: 알아두기 | F1: 다르게 부르는 말 | G1: 약관·특약에서 이렇게 쓰여요 | H1: 예시를 가져온 곳
A2: 1 | B2: 간병·치매 | C2: CDR | D2: 치매가 얼마나 진행됐는지 점수로 나타낸 것이에요. | E2: 0.5는 최경증, 1은 경증, 2는 중등도, 3 이상은 중증이에요. 보험금 기준으로 많이 써요. | F2: 임상치매척도 · 씨디알 | G2: …장애」라 함은 CDR척도… | H2: 약관 본문 · 통합간편 「갱신형 표적치매약물허가치료비 (최경증 치매,경증 알츠하이머치매)」
A3: 2 | B3: 간병·치매 | C3: 간병인 | D3: 입원한 환자 곁에서 식사, 이동, 위생을 돕는 사람이에요. | E3: 하루 12만~15만 원 정도 들어요. | F3: 간병사 · 돌봄인 | G3: 통합간편 「간병인사용 질병입원일당(1일이상 180일한도)(요양병원)」 | H3: 특약 이름 · 이 말이 들어간 특약 110건
A4: 3 | B4: 간병·치매 | C4: 간병인사용 | D4: 보험회사가 간병인을 직접 붙여주거나 그 비용을 대주는 방식이에요. | E4: 내가 간병인을 구해 쓰고 영수증을 내는 형태도 있어요. | F4: 간병인지원 · 간병인 지원 | G4: 통합간편 「간병인사용 질병입원일당(1일이상 180일한도)(요양병원)」 | H4: 특약 이름 · 이 말이 들어간 특약 51건
A5: 4 | B5: 간병·치매 | C5: 간병통합 | D5: 간호사와 간호조무사가 여러 환자의 간병까지 함께 맡는 병실이에요. 이 병실에는 외부 간병인이 들어올 수 없어요. | E5: 간병인을 못 쓰는 대신 이 병실을 쓸 때 주는 담보가 따로 있어요. | F5: 간호간병통합서비스 · 통합간병 · 보호자 없는 병동 | G5: 통합간편 「간호·간병통합서비스 사용 질병입원일당(1일이상 180일한도)」 | H5: 특약 이름 · 이 말이 들어간 특약 18건
A6: 5 | B6: 간병·치매 | C6: 경증치매 | D6: 혼자 생활은 하지만 도움이 필요한 초기 치매예요. | F6: CDR 1 | G6: 통합간편 「갱신형 표적치매약물허가치료비 (최경증 치매,경증 알츠하이머치매)」 | H6: 특약 이름
A7: 6 | B7: 간병·치매 | C7: 노인요양시설 | D7: 치료보다 생활 돌봄을 하는 시설이에요. | E7: 요양병원과 달리 의사가 상주하지 않아 보험 기준이 달라요. | F7: 요양원 | H7: 약관에는 안 나오는 일반 용어
A8: 7 | B8: 간병·치매 | C8: 아밀로이드베타 | D8: 치매 환자의 뇌에 쌓이는 나쁜 단백질 찌꺼기예요. | E8: 이걸 없애는 것이 표적치매치료의 원리예요. | F8: 아밀로이드 · 베타아밀로이드 | G8: 제3조(아밀로이드베타 적응증 상태의… | H8: 약관 본문 · 통합간편 「갱신형 표적치매약물허가치료비 (최경증 치매,경증 알츠하이머치매)」
A9: 8 | B9: 간병·치매 | C9: 알츠하이머치매 | D9: 뇌에 이상 단백질이 쌓여 서서히 기억을 잃는 대표적인 치매예요. | E9: F00, G30 코드에 해당해요. | F9: 알츠하이머 · 알츠하이머병 | G9: 통합간편 「갱신형 표적치매약물허가치료비 (최경증 치매,경증 알츠하이머치매)」 | H9: 특약 이름 · 이 말이 들어간 특약 8건
A10: 9 | B10: 간병·치매 | C10: 요양병원 | D10: 오래 치료와 요양이 필요한 환자가 머무는 병원이에요. | E10: 일반 병원과 구분해 담보 조건이 따로 붙는 경우가 많아요. | F10: 요양원과 다름 · 장기입원병원 | G10: 통합간편 「암요양병원입원일당(Ⅱ)(1일이상 90일한도)」 | H10: 특약 이름 · 이 말이 들어간 특약 69건
A11: 10 | B11: 간병·치매 | C11: 요양성특정질병 | D11: 치매, 파킨슨처럼 오랜 돌봄이 필요한 병들을 묶은 것이에요. | E11: 요양병원 장기입원 담보에서 다뤄요. | F11: 요양성질환 | G11: 통합간편 「갱신형 간병인지원 요양성특정질병입원일당(Ⅰ)(181일이상)(요양병원)」 | H11: 특약 이름 · 이 말이 들어간 특약 7건
A12: 11 | B12: 간병·치매 | C12: 인지지원등급 | D12: 치매가 있지만 신체 기능은 비교적 괜찮은 분에게 주는 등급이에요. | E12: 경증 치매 보장의 기준이 되기도 해요. | F12: 5등급 아래 등급 | H12: 약관에는 안 나오는 일반 용어
A13: 12 | B13: 간병·치매 | C13: 장기요양 | D13: 혼자 생활하기 어려운 어르신을 나라가 등급을 매겨 돌봐주는 제도예요. | E13: 예전에 LTC라고 부르던 것이 바로 이거예요. | F13: LTC · 노인장기요양 | G13: 케어프리 「장기요양급여금(1등급)」 | H13: 특약 이름 · 이 말이 들어간 특약 3건
A14: 13 | B14: 간병·치매 | C14: 장기요양등급 | D14: 돌봄이 얼마나 필요한지를 1~5등급과 인지지원등급으로 나눈 것이에요. | E14: 1등급이 가장 도움이 많이 필요한 상태예요. 보험금 기준으로 자주 써요. | F14: 요양등급 · LTC등급 | G14: 「1등급, 2등급, 3등급 또는 4등급」의 장기요양등급을… | H14: 약관 본문 · 케어프리 「장기요양급여금(1-4등급)」
A15: 14 | B15: 간병·치매 | C15: 중증치매 | D15: 혼자서는 일상생활이 거의 불가능한 상태예요. | E15: 예전 치매보험은 대부분 여기서만 보장했어요. | F15: CDR 3 이상 | G15: 케어프리 「중증치매간병비」 | H15: 특약 이름 · 이 말이 들어간 특약 3건
A16: 15 | B16: 간병·치매 | C16: 최경증치매 | D16: 치매가 막 시작된 아주 초기 단계예요. | E16: 예전에는 보장이 거의 없었지만 최근 담보가 나왔어요. | F16: CDR 0.5 · 아주 초기 치매 | G16: 통합간편 「갱신형 표적치매약물허가치료비 (최경증 치매,경증 알츠하이머치매)」 | H16: 특약 이름
A17: 16 | B17: 간병·치매 | C17: 파킨슨병 | D17: 몸이 떨리고 굳으며 움직임이 느려지는 뇌 질환이에요. | E17: G20 코드예요. 치매와 함께 요양성 질환으로 묶여요. | F17: 파킨슨 | G17: …운동신경세포병, 파킨슨병… | H17: 약관 본문 · 통합간편 「희귀난치성 7대질환진단비」
A18: 17 | B18: 간병·치매 | C18: 표적치매약물 | D18: 치매의 원인인 아밀로이드베타 단백질을 없애 초기 치매 진행을 늦추는 치료제예요. 레켐비가 대표적이에요. | E18: 2주 간격으로 오래 맞아야 해서 횟수별 담보가 필요해요. | F18: 표적치매치료 · 레켐비 · 아밀로이드 제거제 | G18: 통합간편 「갱신형 표적치매약물허가치료비 (최경증 치매,경증 알츠하이머치매)」 | H18: 특약 이름 · 이 말이 들어간 특약 8건
A19: 18 | B19: 간병·치매 | C19: 혈관성치매 | D19: 뇌졸중 등으로 뇌혈관이 망가져 생기는 치매예요. | E19: 갑자기 나빠지는 특징이 있어요. | F19: 혈관치매 | H19: 약관에는 안 나오는 일반 용어
A20: 19 | B20: 검사·진단 | C20: TNM | D20: 암 덩어리 크기(T), 림프절 전이(N), 다른 장기 전이(M)로 병기를 정하는 방법이에요. | E20: 의학적으로 가장 널리 쓰는 기준이에요. | F20: TNM 분류 | G20: …세우고 예후를 예측하는데 사용되며 기본적으로 TNM… | H20: 약관 본문 · 통합간편 「원격전이포함 4기 통합암진단비(유사암제외)」
A21: 20 | B21: 검사·진단 | C21: 건강검진 | D21: 몸 상태를 전반적으로 확인하는 검사예요. | E21: 여기서 초기 암이 발견되는 경우가 늘고 있어요. | F21: 종합검진 | G21: …질병으로 추가 진단(단순 건강검진 제외)… | H21: 약관 본문 · 통합간편 「갱신형 가족일상생활중배상책임(Ⅳ)」
A22: 21 | B22: 검사·진단 | C22: 골밀도 | D22: 뼈가 얼마나 단단한지 재는 검사예요. | E22: 골다공증을 찾아내요. | F22: 골밀도검사 · BMD | G22: …제3절 핵의학영상진단 및 골밀도검사… | H22: 약관 본문 · 통합간편 「암 통합치료비(기본형)」
A23: 22 | B23: 검사·진단 | C23: 국가암검진 | D23: 나라에서 정한 나이가 되면 무료 또는 저렴하게 받는 암 검사예요. | E23: 위·대장·간·유방·자궁경부·폐 6대 암이 대상이에요. | F23: 암검진 · 공단검진 | H23: 약관에는 안 나오는 일반 용어
A24: 23 | B24: 검사·진단 | C24: 내시경 | D24: 가느다란 카메라를 몸속에 넣어 직접 들여다보는 검사예요. | E24: 검사 중에 용종을 떼어내면 수술로 인정되기도 해요. | F24: 내시경검사 · 위내시경 · 대장내시경 | G24: 통합간편 「갱신형 암 내시경검사비 (급여, 연간1회한)」 | H24: 특약 이름 · 이 말이 들어간 특약 2건
A25: 24 | B25: 검사·진단 | C25: 면역조직화학검사 | D25: 조직에 특별한 시약을 묻혀 암의 성질을 자세히 알아내는 검사예요. | E25: 표적항암제를 쓸 수 있는지 판단할 때 써요. | F25: IHC · 면역염색 | H25: 약관에는 안 나오는 일반 용어
A26: 25 | B26: 검사·진단 | C26: 소견서 | D26: 진단서보다 간단하게 의사의 의견을 적은 문서예요. | E26: 진단서 대신 인정되지 않는 경우도 있어요. | F26: 의사 소견서 | G26: …진료비세부내역서, 진단서, 의사소견서… | H26: 약관 본문 · 통합간편 「암 통합치료비(기본형)」
A27: 26 | B27: 검사·진단 | C27: 수술기록지 | D27: 어떤 수술을 언제 받았는지 확인해 주는 서류예요. | E27: 수술비 청구에 필요해요. | F27: 수술확인서 | G27: …및 수술기록지 등 포함)… | H27: 약관 본문 · 통합간편 「상해 통합치료비(실속형)」
A28: 27 | B28: 검사·진단 | C28: 심장초음파 | D28: 심장의 움직임과 판막 상태를 초음파로 보는 검사예요. | F28: 심초음파 | G28: …병력과 함께 심전도, 심장초음파… | H28: 약관 본문 · 통합간편 「급성심근경색증입원일당(4일이상)」
A29: 28 | B29: 검사·진단 | C29: 심전도 | D29: 심장의 전기 신호를 그림으로 그려 부정맥을 찾는 검사예요. | F29: ECG · EKG | G29: …중앙공급식 의료가스시설, 심전도… | H29: 약관 본문 · 통합간편 「상해 통합치료비(실속형)」
A30: 29 | B30: 검사·진단 | C30: 유전자검사 | D30: 암세포의 유전자를 분석해 어떤 약이 잘 들을지 찾는 검사예요. | E30: 맞춤 항암치료의 출발점이에요. | F30: 돌연변이검사 · NGS | G30: 통합간편 「갱신형 암 특정단일유전자검사비 (급여,연간1회한)」 | H30: 특약 이름 · 이 말이 들어간 특약 2건
A31: 30 | B31: 검사·진단 | C31: 입원확인서 | D31: 언제 입원하고 퇴원했는지 증명하는 서류예요. | E31: 입원일당 청구에 필요해요. | F31: 입퇴원확인서 | G31: …입원확인서를 변조하여 입원 일수 30일에… | H31: 약관 본문 · 통합간편 「갱신형 가족일상생활중배상책임(Ⅳ)」
A32: 31 | B32: 검사·진단 | C32: 조영술 | D32: 혈관에 조영제를 넣고 촬영해 막힌 곳을 찾는 검사예요. | E32: 심장과 뇌혈관 진단의 기본이에요. | F32: 혈관조영술 · 앤지오 | G32: 관조영술, 관상동맥조영술, 대동맥조영술 등… | H32: 약관 본문 · 통합간편 「특정순환계질환진단비」
A33: 32 | B33: 검사·진단 | C33: 조직검사 | D33: 몸에서 아주 작은 조각을 떼어 현미경으로 확인하는 검사예요. | E33: 암 진단을 확정하는 가장 확실한 방법이에요. | F33: 바이옵시 | G33: …피보험자가 조직검사 등 병리학적 검사를… | H33: 약관 본문 · 통합간편 「5대고액치료비암진단비」
A34: 33 | B34: 검사·진단 | C34: 종양표지자 | D34: 피 속에 암이 있을 때 늘어나는 물질을 재는 검사예요. | E34: 이것만으로 암을 확정하지는 않아요. | F34: 암표지자 | H34: 약관에는 안 나오는 일반 용어
A35: 34 | B35: 검사·진단 | C35: 진단서 | D35: 의사가 병명과 상태를 적어 발급하는 공식 문서예요. | E35: 보험금 청구의 기본 서류예요. | F35: 의사 진단서 | G35: …기준으로 진단서 및 진료비 세부내역서… | H35: 약관 본문 · 통합간편 「수술비(1-7종, 연간3회한)[상해]」
A36: 35 | B36: 검사·진단 | C36: 진료기록부 | D36: 의사가 진료한 내용을 적어 병원에 보관하는 공식 기록이에요. | E36: 보험금 청구 때 진단 경위를 확인하는 근거 서류로 쓰여요. | G36: …인정하는 경우에는 검사결과, 진료기록부의… | H36: 약관 본문 · 통합간편 「신화상치료비」
A37: 36 | B37: 검사·진단 | C37: 초음파 | D37: 몸에 들리지 않는 소리를 쏘아 장기를 들여다보는 검사예요. | E37: 방사선이 없어 안전하고 임신부도 받을 수 있어요. | F37: 초음파검사 | G37: 통합간편 「갱신형 암 초음파검사비 (급여,연간1회한)」 | H37: 특약 이름 · 이 말이 들어간 특약 2건
A38: 37 | B38: 계약·제도 | C38: 가지급 | D38: 보험금 심사가 길어질 때 일부를 먼저 주는 제도예요. | E38: 나중에 최종 금액에서 정산해요. | F38: 가지급보험금 · 선지급 | G38: …변동에 따라 미지급된 보험금을 추가지급하거나… | H38: 약관 본문 · 통합간편 「민사소송법률비용」
A39: 38 | B39: 계약·제도 | C39: 감액(계약변경) | D39: 이미 가입한 보험의 가입금액을 줄이는 것이에요. 줄인 만큼 보험료도 줄어요. | E39: 보험료가 부담될 때 해지 대신 쓸 수 있는 방법이에요. | F39: 가입금액 감액 | H39: 약관에는 안 나오는 일반 용어
A40: 39 | B40: 계약·제도 | C40: 감액기간 | D40: 보장은 되지만 정해진 기간 동안은 보험금을 절반처럼 일부만 주는 기간이에요. | E40: 보통 1~2년이며, 이 기간이 지나면 100% 지급돼요. | F40: 삭감기간 | G40: 통합간편 「뇌졸중진단비(감액기간미적용)」 | H40: 특약 이름 · 이 말이 들어간 특약 15건
...

Sheet 분류별 개수
A1: 분류 | B1: 용어 수 | C1: 약관 예시가 있는 것 | D1: 예시 비율
A2: 간병·치매 | B2: =COUNTIF(보험용어사전!$B$2:$B$389,$A2) | C2: =COUNTIFS(보험용어사전!$B$2:$B$389,$A2,보험용어사전!$H$2:$H$389,"<>약관에는 안 나오는 일반 용어") | D2: =IFERROR($C2/$B2,0)
A3: 검사·진단 | B3: =COUNTIF(보험용어사전!$B$2:$B$389,$A3) | C3: =COUNTIFS(보험용어사전!$B$2:$B$389,$A3,보험용어사전!$H$2:$H$389,"<>약관에는 안 나오는 일반 용어") | D3: =IFERROR($C3/$B3,0)
A4: 계약·제도 | B4: =COUNTIF(보험용어사전!$B$2:$B$389,$A4) | C4: =COUNTIFS(보험용어사전!$B$2:$B$389,$A4,보험용어사전!$H$2:$H$389,"<>약관에는 안 나오는 일반 용어") | D4: =IFERROR($C4/$B4,0)
A5: 급여·의료비 | B5: =COUNTIF(보험용어사전!$B$2:$B$389,$A5) | C5: =COUNTIFS(보험용어사전!$B$2:$B$389,$A5,보험용어사전!$H$2:$H$389,"<>약관에는 안 나오는 일반 용어") | D5: =IFERROR($C5/$B5,0)
A6: 기타질환 | B6: =COUNTIF(보험용어사전!$B$2:$B$389,$A6) | C6: =COUNTIFS(보험용어사전!$B$2:$B$389,$A6,보험용어사전!$H$2:$H$389,"<>약관에는 안 나오는 일반 용어") | D6: =IFERROR($C6/$B6,0)
A7: 뇌·심장 | B7: =COUNTIF(보험용어사전!$B$2:$B$389,$A7) | C7: =COUNTIFS(보험용어사전!$B$2:$B$389,$A7,보험용어사전!$H$2:$H$389,"<>약관에는 안 나오는 일반 용어") | D7: =IFERROR($C7/$B7,0)
A8: 보험금·지급 | B8: =COUNTIF(보험용어사전!$B$2:$B$389,$A8) | C8: =COUNTIFS(보험용어사전!$B$2:$B$389,$A8,보험용어사전!$H$2:$H$389,"<>약관에는 안 나오는 일반 용어") | D8: =IFERROR($C8/$B8,0)
A9: 상해·장해 | B9: =COUNTIF(보험용어사전!$B$2:$B$389,$A9) | C9: =COUNTIFS(보험용어사전!$B$2:$B$389,$A9,보험용어사전!$H$2:$H$389,"<>약관에는 안 나오는 일반 용어") | D9: =IFERROR($C9/$B9,0)
A10: 수술·치료 | B10: =COUNTIF(보험용어사전!$B$2:$B$389,$A10) | C10: =COUNTIFS(보험용어사전!$B$2:$B$389,$A10,보험용어사전!$H$2:$H$389,"<>약관에는 안 나오는 일반 용어") | D10: =IFERROR($C10/$B10,0)
A11: 암 | B11: =COUNTIF(보험용어사전!$B$2:$B$389,$A11) | C11: =COUNTIFS(보험용어사전!$B$2:$B$389,$A11,보험용어사전!$H$2:$H$389,"<>약관에는 안 나오는 일반 용어") | D11: =IFERROR($C11/$B11,0)
A12: 운전자·교통 | B12: =COUNTIF(보험용어사전!$B$2:$B$389,$A12) | C12: =COUNTIFS(보험용어사전!$B$2:$B$389,$A12,보험용어사전!$H$2:$H$389,"<>약관에는 안 나오는 일반 용어") | D12: =IFERROR($C12/$B12,0)
A13: 유병자·심사 | B13: =COUNTIF(보험용어사전!$B$2:$B$389,$A13) | C13: =COUNTIFS(보험용어사전!$B$2:$B$389,$A13,보험용어사전!$H$2:$H$389,"<>약관에는 안 나오는 일반 용어") | D13: =IFERROR($C13/$B13,0)
... A16: 태아·어린이 | B16: =COUNTIF(보험용어사전!$B$2:$B$389,$A16) | C16: =COUNTIFS(보험용어사전!$B$2:$B$389,$A16,보험용어사전!$H$2:$H$389,"<>약관에는 안 나오는 일반 용어") | D16: =IFERROR($C16/$B16,0)
A17: 합계 | B17: =SUM(B2:B16) | C17: =SUM(C2:C16) | D17: =IFERROR($C17/$B17,0)
